Workbook

Sheet START
A1: EASY EWI STOCK TRACKER — NO ROW LIMIT
A2: You can keep adding movement rows to the MOVEMENTS table.
A3: Do NOT type into the STOCK sheet except the starting quantities.
A4: For a new delivery/use/return, add a new row inside the MOVEMENTS table.
A5: The STOCK formulas use whole columns, so new movement rows are included automatically.
A7: Example: Glue starts 100.
A8: Deliver 14 → stock 86.
A9: Deliver 2 more → stock 84.
A10: Return 2 → stock 86.
A11: Use 3 → stock 83.

Sheet MOVEMENTS
A1: Date | B1: House ID | C1: Postcode / Eircode | D1: Material | E1: Qty | F1: Movement | G1: Notes | H1: Material ID | I1: House Owner Name | J1: Delivered By | K1: Worker Team | L1: Column1
A2: 03/09/2026 | B2: test | C2: F26 ABC1 | D2: Mortage bags(Glue) | E2: 0 | F2: Delivery to House | G2: First delivery
A3: 03/09/2026 | B3: test | C3: F26 ABC1 | D3: Mortage bags(Glue) | E3: 0 | F3: Return to Warehouse | G3: Left over | H3: 13045
A4: 05/09/2026 | B4: test | C4: F26 ABC1 | D4: Soil bend 110mm x 90deg S/S black | E4: 0 | F4: Delivery to House | G4: Extra delivery
A5: 12/09/2026 | B5: test | C5: F26 ABC1 | D5: Soil bend 110mm x 90deg S/S black | E5: 0 | F5: Return to Warehouse | G5: Left over
A6: 04/09/2026 | B6: test | C6: F26 DEF2 | D6: Board 20mm white | E6: 0 | F6: Delivery to House | G6: First delivery | H6: 12236
A7: 07/09/2026 | B7: test | C7: F26 DEF2 | D7: Glue | E7: 0 | F7: Delivery to House | G7: Extra delivery
A8: 04/09/2026 | B8: test | C8: F26 GHI3 | D8: Window profile (2.4m) | E8: 0 | F8: Delivery to House | G8: First delivery | H8: 20921
A9: 14/09/2026 | B9: test | C9: F26 GHI3 | D9: Window profile (2.4m) | E9: 0 | F9: Return to Warehouse | G9: Left over | H9: 20921
A10: 14/09/2027 | B10: test | C10: asfasdsa | D10: Starter track 100mm (2m) | E10: 0 | F10: Delivery to House | G10: First delivery | H10: 22593
A11: 14/09/2027 | B11: test | C11: asfasdsa | D11: Starter track 100mm (2m) | E11: 0 | F11: Return to Warehouse | G11: Left over | H11: 22593
A12: 14/09/2028 | B12: test | C12: aaaaa | D12: Downpipe brackets short brown | E12: 0 | F12: Delivery to House | G12: First delivery
A13: 14/09/2028 | B13: test | C13: aaaaa | D13: Downpipe brackets short brown | E13: 0 | F13: Return to Warehouse | G13: Left over | L13: Delivery to House
A14: 14/09/2029 | B14: test | C14: dwedw | D14: Boby bag | E14: 0 | F14: Delivery to House | G14: First delivery | L14: Return to Warehouse
A15: 46275 | B15: Wh625830 | C15: f56a097 | D15: Gun foam fp404 pink | E15: 5 | F15: Delivery to House | G15: Second delivery | I15: Christy McGuinn | J15: Karol | K15: Davit's team(Jemo)
A16: 46275 | B16: WH620171 | C16: F26KX82 | D16: Board 100mm | E16: 12 | F16: Return to Warehouse | G16: Left over | I16: Sarah Ginnely | J16: Gary | K16: Davit's team(Jemo)
A17: 46275 | B17: WH620171 | C17: F26KX82 | D17: Mortage bags(Glue) | E17: 2.5 | F17: Return to Warehouse | G17: Left over | I17: Sarah Ginnely | J17: Gary | K17: Davit's team(Jemo)
A18: 46275 | B18: WH620171 | C18: F26KX82 | D18: Primer | E18: 1.5 | F18: Return to Warehouse | G18: Left over | I18: Sarah Ginnely | J18: Gary | K18: Davit's team(Jemo)
A19: 46275 | B19: WH620171 | C19: F26KX82 | D19: Downpipe white | E19: 1 | F19: Return to Warehouse | I19: Sarah Ginnely | J19: Gary | K19: Davit's team(Jemo)

Sheet STOCK
A1: Material ID | B1: Material | C1: Starting Stock | D1: Delivered | E1: Returned | F1: Used | G1: CURRENT STOCK | H1: Comment
A2: 22565 | B2: Mortage bags(Glue) | C2: 142 | D2: =SUMIFS(MOVEMENTS!$E:$E,MOVEMENTS!$D:$D,$B2,MOVEMENTS!$F:$F,"Delivery to House") | E2: =SUMIFS(MOVEMENTS!$E:$E,MOVEMENTS!$D:$D,$B2,MOVEMENTS!$F:$F,"Return to Warehouse") | F2: =SUMIFS(MOVEMENTS!$E:$E,MOVEMENTS!$D:$D,$B2,MOVEMENTS!$F:$F,"Used on House") | G2: =C2-D2+E2-F2
A3: 13045 | B3: Board 100mm | C3: 113 | D3: =SUMIFS(MOVEMENTS!$E:$E,MOVEMENTS!$D:$D,$B3,MOVEMENTS!$F:$F,"Delivery to House") | E3: =SUMIFS(MOVEMENTS!$E:$E,MOVEMENTS!$D:$D,$B3,MOVEMENTS!$F:$F,"Return to Warehouse") | F3: =SUMIFS(MOVEMENTS!$E:$E,MOVEMENTS!$D:$D,$B3,MOVEMENTS!$F:$F,"Used on House") | G3: =C3-D3+E3-F3
B4: Board 60mm | C4: 97 | D4: =SUMIFS(MOVEMENTS!$E:$E,MOVEMENTS!$D:$D,$B4,MOVEMENTS!$F:$F,"Delivery to House") | E4: =SUMIFS(MOVEMENTS!$E:$E,MOVEMENTS!$D:$D,$B4,MOVEMENTS!$F:$F,"Return to Warehouse") | F4: =SUMIFS(MOVEMENTS!$E:$E,MOVEMENTS!$D:$D,$B4,MOVEMENTS!$F:$F,"Used on House") | G4: =C4-D4+E4-F4
B5: Board 60mm Pink | C5: 47 | D5: =SUMIFS(MOVEMENTS!$E:$E,MOVEMENTS!$D:$D,$B5,MOVEMENTS!$F:$F,"Delivery to House") | E5: =SUMIFS(MOVEMENTS!$E:$E,MOVEMENTS!$D:$D,$B5,MOVEMENTS!$F:$F,"Return to Warehouse") | F5: =SUMIFS(MOVEMENTS!$E:$E,MOVEMENTS!$D:$D,$B5,MOVEMENTS!$F:$F,"Used on House") | G5: =C5-D5+E5-F5
A6: 12236 | B6: Board 20mm white | C6: 12 | D6: =SUMIFS(MOVEMENTS!$E:$E,MOVEMENTS!$D:$D,$B6,MOVEMENTS!$F:$F,"Delivery to House") | E6: =SUMIFS(MOVEMENTS!$E:$E,MOVEMENTS!$D:$D,$B6,MOVEMENTS!$F:$F,"Return to Warehouse") | F6: =SUMIFS(MOVEMENTS!$E:$E,MOVEMENTS!$D:$D,$B6,MOVEMENTS!$F:$F,"Used on House") | G6: =C6-D6+E6-F6
B7: Board 10mm white | C7: 32 | D7: =SUMIFS(MOVEMENTS!$E:$E,MOVEMENTS!$D:$D,$B7,MOVEMENTS!$F:$F,"Delivery to House") | E7: =SUMIFS(MOVEMENTS!$E:$E,MOVEMENTS!$D:$D,$B7,MOVEMENTS!$F:$F,"Return to Warehouse") | F7: =SUMIFS(MOVEMENTS!$E:$E,MOVEMENTS!$D:$D,$B7,MOVEMENTS!$F:$F,"Used on House") | G7: =C7-D7+E7-F7
B8: Rockwool 100mm | C8: 0 | D8: =SUMIFS(MOVEMENTS!$E:$E,MOVEMENTS!$D:$D,$B8,MOVEMENTS!$F:$F,"Delivery to House") | E8: =SUMIFS(MOVEMENTS!$E:$E,MOVEMENTS!$D:$D,$B8,MOVEMENTS!$F:$F,"Return to Warehouse") | F8: =SUMIFS(MOVEMENTS!$E:$E,MOVEMENTS!$D:$D,$B8,MOVEMENTS!$F:$F,"Used on House") | G8: =C8-D8+E8-F8
B9: Rockwool 120mm | C9: 58 | D9: =SUMIFS(MOVEMENTS!$E:$E,MOVEMENTS!$D:$D,$B9,MOVEMENTS!$F:$F,"Delivery to House") | E9: =SUMIFS(MOVEMENTS!$E:$E,MOVEMENTS!$D:$D,$B9,MOVEMENTS!$F:$F,"Return to Warehouse") | F9: =SUMIFS(MOVEMENTS!$E:$E,MOVEMENTS!$D:$D,$B9,MOVEMENTS!$F:$F,"Used on House") | G9: =C9-D9+E9-F9
A10: 22593 | B10: Starter track 100mm (2m) | C10: 125 | D10: =SUMIFS(MOVEMENTS!$E:$E,MOVEMENTS!$D:$D,$B10,MOVEMENTS!$F:$F,"Delivery to House") | E10: =SUMIFS(MOVEMENTS!$E:$E,MOVEMENTS!$D:$D,$B10,MOVEMENTS!$F:$F,"Return to Warehouse") | F10: =SUMIFS(MOVEMENTS!$E:$E,MOVEMENTS!$D:$D,$B10,MOVEMENTS!$F:$F,"Used on House") | G10: =C10-D10+E10-F10
B11: Aluminum starter track 100mm (2.5m) | C11: 16 | D11: =SUMIFS(MOVEMENTS!$E:$E,MOVEMENTS!$D:$D,$B11,MOVEMENTS!$F:$F,"Delivery to House") | E11: =SUMIFS(MOVEMENTS!$E:$E,MOVEMENTS!$D:$D,$B11,MOVEMENTS!$F:$F,"Return to Warehouse") | F11: =SUMIFS(MOVEMENTS!$E:$E,MOVEMENTS!$D:$D,$B11,MOVEMENTS!$F:$F,"Used on House") | G11: =C11-D11+E11-F11
A12: 20921 | B12: Window profile (2.4m) | C12: 32 | D12: =SUMIFS(MOVEMENTS!$E:$E,MOVEMENTS!$D:$D,$B12,MOVEMENTS!$F:$F,"Delivery to House") | E12: =SUMIFS(MOVEMENTS!$E:$E,MOVEMENTS!$D:$D,$B12,MOVEMENTS!$F:$F,"Return to Warehouse") | F12: =SUMIFS(MOVEMENTS!$E:$E,MOVEMENTS!$D:$D,$B12,MOVEMENTS!$F:$F,"Used on House") | G12: =C12-D12+E12-F12
A13: 22502 | B13: Corner bit (2.5m) | C13: 108 | D13: =SUMIFS(MOVEMENTS!$E:$E,MOVEMENTS!$D:$D,$B13,MOVEMENTS!$F:$F,"Delivery to House") | E13: =SUMIFS(MOVEMENTS!$E:$E,MOVEMENTS!$D:$D,$B13,MOVEMENTS!$F:$F,"Return to Warehouse") | F13: =SUMIFS(MOVEMENTS!$E:$E,MOVEMENTS!$D:$D,$B13,MOVEMENTS!$F:$F,"Used on House") | G13: =C13-D13+E13-F13
A14: 41318 | B14: Pins 155mm | C14: 2900 | D14: =SUMIFS(MOVEMENTS!$E:$E,MOVEMENTS!$D:$D,$B14,MOVEMENTS!$F:$F,"Delivery to House") | E14: =SUMIFS(MOVEMENTS!$E:$E,MOVEMENTS!$D:$D,$B14,MOVEMENTS!$F:$F,"Return to Warehouse") | F14: =SUMIFS(MOVEMENTS!$E:$E,MOVEMENTS!$D:$D,$B14,MOVEMENTS!$F:$F,"Used on House") | G14: =C14-D14+E14-F14
B15: Pins 95mm | C15: 2400 | D15: =SUMIFS(MOVEMENTS!$E:$E,MOVEMENTS!$D:$D,$B15,MOVEMENTS!$F:$F,"Delivery to House") | E15: =SUMIFS(MOVEMENTS!$E:$E,MOVEMENTS!$D:$D,$B15,MOVEMENTS!$F:$F,"Return to Warehouse") | F15: =SUMIFS(MOVEMENTS!$E:$E,MOVEMENTS!$D:$D,$B15,MOVEMENTS!$F:$F,"Used on House") | G15: =C15-D15+E15-F15
B16: Polystyrene disc | C16: 6000 | D16: =SUMIFS(MOVEMENTS!$E:$E,MOVEMENTS!$D:$D,$B16,MOVEMENTS!$F:$F,"Delivery to House") | E16: =SUMIFS(MOVEMENTS!$E:$E,MOVEMENTS!$D:$D,$B16,MOVEMENTS!$F:$F,"Return to Warehouse") | F16: =SUMIFS(MOVEMENTS!$E:$E,MOVEMENTS!$D:$D,$B16,MOVEMENTS!$F:$F,"Used on House") | G16: =C16-D16+E16-F16
A17: 22501 | B17: Mesh | C17: 7 | D17: =SUMIFS(MOVEMENTS!$E:$E,MOVEMENTS!$D:$D,$B17,MOVEMENTS!$F:$F,"Delivery to House") | E17: =SUMIFS(MOVEMENTS!$E:$E,MOVEMENTS!$D:$D,$B17,MOVEMENTS!$F:$F,"Return to Warehouse") | F17: =SUMIFS(MOVEMENTS!$E:$E,MOVEMENTS!$D:$D,$B17,MOVEMENTS!$F:$F,"Used on House") | G17: =C17-D17+E17-F17
B18: Spacers 5mm | C18: 18 | D18: =SUMIFS(MOVEMENTS!$E:$E,MOVEMENTS!$D:$D,$B18,MOVEMENTS!$F:$F,"Delivery to House") | E18: =SUMIFS(MOVEMENTS!$E:$E,MOVEMENTS!$D:$D,$B18,MOVEMENTS!$F:$F,"Return to Warehouse") | F18: =SUMIFS(MOVEMENTS!$E:$E,MOVEMENTS!$D:$D,$B18,MOVEMENTS!$F:$F,"Used on House") | G18: =C18-D18+E18-F18
B19: Spacers 3mm | C19: 12 | D19: =SUMIFS(MOVEMENTS!$E:$E,MOVEMENTS!$D:$D,$B19,MOVEMENTS!$F:$F,"Delivery to House") | E19: =SUMIFS(MOVEMENTS!$E:$E,MOVEMENTS!$D:$D,$B19,MOVEMENTS!$F:$F,"Return to Warehouse") | F19: =SUMIFS(MOVEMENTS!$E:$E,MOVEMENTS!$D:$D,$B19,MOVEMENTS!$F:$F,"Used on House") | G19: =C19-D19+E19-F19
B20: Fisher fixing | C20: 1000 | D20: =SUMIFS(MOVEMENTS!$E:$E,MOVEMENTS!$D:$D,$B20,MOVEMENTS!$F:$F,"Delivery to House") | E20: =SUMIFS(MOVEMENTS!$E:$E,MOVEMENTS!$D:$D,$B20,MOVEMENTS!$F:$F,"Return to Warehouse") | F20: =SUMIFS(MOVEMENTS!$E:$E,MOVEMENTS!$D:$D,$B20,MOVEMENTS!$F:$F,"Used on House") | G20: =C20-D20+E20-F20
B21: Plugs (6/60)mm | C21: ? | D21: =SUMIFS(MOVEMENTS!$E:$E,MOVEMENTS!$D:$D,$B21,MOVEMENTS!$F:$F,"Delivery to House") | E21: =SUMIFS(MOVEMENTS!$E:$E,MOVEMENTS!$D:$D,$B21,MOVEMENTS!$F:$F,"Return to Warehouse") | F21: =SUMIFS(MOVEMENTS!$E:$E,MOVEMENTS!$D:$D,$B21,MOVEMENTS!$F:$F,"Used on House") | G21: =C21-D21+E21-F21
B22: Exp tape | C22: 148 | D22: =SUMIFS(MOVEMENTS!$E:$E,MOVEMENTS!$D:$D,$B22,MOVEMENTS!$F:$F,"Delivery to House") | E22: =SUMIFS(MOVEMENTS!$E:$E,MOVEMENTS!$D:$D,$B22,MOVEMENTS!$F:$F,"Return to Warehouse") | F22: =SUMIFS(MOVEMENTS!$E:$E,MOVEMENTS!$D:$D,$B22,MOVEMENTS!$F:$F,"Used on House") | G22: =C22-D22+E22-F22
B23: Metal pins for rockwool | C23: 200 | D23: =SUMIFS(MOVEMENTS!$E:$E,MOVEMENTS!$D:$D,$B23,MOVEMENTS!$F:$F,"Delivery to House") | E23: =SUMIFS(MOVEMENTS!$E:$E,MOVEMENTS!$D:$D,$B23,MOVEMENTS!$F:$F,"Return to Warehouse") | F23: =SUMIFS(MOVEMENTS!$E:$E,MOVEMENTS!$D:$D,$B23,MOVEMENTS!$F:$F,"Used on House") | G23: =C23-D23+E23-F23
A24: 29574 | B24: Gun foam fp404 pink | C24: 36 | D24: =SUMIFS(MOVEMENTS!$E:$E,MOVEMENTS!$D:$D,$B24,MOVEMENTS!$F:$F,"Delivery to House") | E24: =SUMIFS(MOVEMENTS!$E:$E,MOVEMENTS!$D:$D,$B24,MOVEMENTS!$F:$F,"Return to Warehouse") | F24: =SUMIFS(MOVEMENTS!$E:$E,MOVEMENTS!$D:$D,$B24,MOVEMENTS!$F:$F,"Used on House") | G24: =C24-D24+E24-F24
B25: Gun foam yellow | C25: 0 | D25: =SUMIFS(MOVEMENTS!$E:$E,MOVEMENTS!$D:$D,$B25,MOVEMENTS!$F:$F,"Delivery to House") | E25: =SUMIFS(MOVEMENTS!$E:$E,MOVEMENTS!$D:$D,$B25,MOVEMENTS!$F:$F,"Return to Warehouse") | F25: =SUMIFS(MOVEMENTS!$E:$E,MOVEMENTS!$D:$D,$B25,MOVEMENTS!$F:$F,"Used on House") | G25: =C25-D25+E25-F25
B26: Finish cout (White) | C26: 37 | D26: =SUMIFS(MOVEMENTS!$E:$E,MOVEMENTS!$D:$D,$B26,MOVEMENTS!$F:$F,"Delivery to House") | E26: =SUMIFS(MOVEMENTS!$E:$E,MOVEMENTS!$D:$D,$B26,MOVEMENTS!$F:$F,"Return to Warehouse") | F26: =SUMIFS(MOVEMENTS!$E:$E,MOVEMENTS!$D:$D,$B26,MOVEMENTS!$F:$F,"Used on House") | G26: =C26-D26+E26-F26
A27: 22616 | B27: Finish cout (Light grey 0938) | C27: 74 | D27: =SUMIFS(MOVEMENTS!$E:$E,MOVEMENTS!$D:$D,$B27,MOVEMENTS!$F:$F,"Delivery to House") | E27: =SUMIFS(MOVEMENTS!$E:$E,MOVEMENTS!$D:$D,$B27,MOVEMENTS!$F:$F,"Return to Warehouse") | F27: =SUMIFS(MOVEMENTS!$E:$E,MOVEMENTS!$D:$D,$B27,MOVEMENTS!$F:$F,"Used on House") | G27: =C27-D27+E27-F27
B28: Finish cout (Light cream 0198) | C28: 0 | D28: =SUMIFS(MOVEMENTS!$E:$E,MOVEMENTS!$D:$D,$B28,MOVEMENTS!$F:$F,"Delivery to House") | E28: =SUMIFS(MOVEMENTS!$E:$E,MOVEMENTS!$D:$D,$B28,MOVEMENTS!$F:$F,"Return to Warehouse") | F28: =SUMIFS(MOVEMENTS!$E:$E,MOVEMENTS!$D:$D,$B28,MOVEMENTS!$F:$F,"Used on House") | G28: =C28-D28+E28-F28
B29: Finish cout (Dark cream 0298) | C29: 49 | D29: =SUMIFS(MOVEMENTS!$E:$E,MOVEMENTS!$D:$D,$B29,MOVEMENTS!$F:$F,"Delivery to House") | E29: =SUMIFS(MOVEMENTS!$E:$E,MOVEMENTS!$D:$D,$B29,MOVEMENTS!$F:$F,"Return to Warehouse") | F29: =SUMIFS(MOVEMENTS!$E:$E,MOVEMENTS!$D:$D,$B29,MOVEMENTS!$F:$F,"Used on House") | G29: =C29-D29+E29-F29
B30: Primer | C30: 12 | D30: =SUMIFS(MOVEMENTS!$E:$E,MOVEMENTS!$D:$D,$B30,MOVEMENTS!$F:$F,"Delivery to House") | E30: =SUMIFS(MOVEMENTS!$E:$E,MOVEMENTS!$D:$D,$B30,MOVEMENTS!$F:$F,"Return to Warehouse") | F30: =SUMIFS(MOVEMENTS!$E:$E,MOVEMENTS!$D:$D,$B30,MOVEMENTS!$F:$F,"Used on House") | G30: =C30-D30+E30-F30
B31: ESB clips | C31: 500 | D31: =SUMIFS(MOVEMENTS!$E:$E,MOVEMENTS!$D:$D,$B31,MOVEMENTS!$F:$F,"Delivery to House") | E31: =SUMIFS(MOVEMENTS!$E:$E,MOVEMENTS!$D:$D,$B31,MOVEMENTS!$F:$F,"Return to Warehouse") | F31: =SUMIFS(MOVEMENTS!$E:$E,MOVEMENTS!$D:$D,$B31,MOVEMENTS!$F:$F,"Used on House") | G31: =C31-D31+E31-F31
B32: Pins for ext cable | C32: 3 | D32: =SUMIFS(MOVEMENTS!$E:$E,MOVEMENTS!$D:$D,$B32,MOVEMENTS!$F:$F,"Delivery to House") | E32: =SUMIFS(MOVEMENTS!$E:$E,MOVEMENTS!$D:$D,$B32,MOVEMENTS!$F:$F,"Return to Warehouse") | F32: =SUMIFS(MOVEMENTS!$E:$E,MOVEMENTS!$D:$D,$B32,MOVEMENTS!$F:$F,"Used on House") | G32: =C32-D32+E32-F32
B33: Caping white 100mm | C33: 77 | D33: =SUMIFS(MOVEMENTS!$E:$E,MOVEMENTS!$D:$D,$B33,MOVEMENTS!$F:$F,"Delivery to House") | E33: =SUMIFS(MOVEMENTS!$E:$E,MOVEMENTS!$D:$D,$B33,MOVEMENTS!$F:$F,"Return to Warehouse") | F33: =SUMIFS(MOVEMENTS!$E:$E,MOVEMENTS!$D:$D,$B33,MOVEMENTS!$F:$F,"Used on House") | G33: =C33-D33+E33-F33
B34: Caping black 100mm | C34: 78 | D34: =SUMIFS(MOVEMENTS!$E:$E,MOVEMENTS!$D:$D,$B34,MOVEMENTS!$F:$F,"Delivery to House") | E34: =SUMIFS(MOVEMENTS!$E:$E,MOVEMENTS!$D:$D,$B34,MOVEMENTS!$F:$F,"Return to Warehouse") | F34: =SUMIFS(MOVEMENTS!$E:$E,MOVEMENTS!$D:$D,$B34,MOVEMENTS!$F:$F,"Used on House") | G34: =C34-D34+E34-F34
B35: Caping brown 100mm | C35: 49 | D35: =SUMIFS(MOVEMENTS!$E:$E,MOVEMENTS!$D:$D,$B35,MOVEMENTS!$F:$F,"Delivery to House") | E35: =SUMIFS(MOVEMENTS!$E:$E,MOVEMENTS!$D:$D,$B35,MOVEMENTS!$F:$F,"Return to Warehouse") | F35: =SUMIFS(MOVEMENTS!$E:$E,MOVEMENTS!$D:$D,$B35,MOVEMENTS!$F:$F,"Used on House") | G35: =C35-D35+E35-F35
B36: Caping joiner white | C36: 93 | D36: =SUMIFS(MOVEMENTS!$E:$E,MOVEMENTS!$D:$D,$B36,MOVEMENTS!$F:$F,"Delivery to House") | E36: =SUMIFS(MOVEMENTS!$E:$E,MOVEMENTS!$D:$D,$B36,MOVEMENTS!$F:$F,"Return to Warehouse") | F36: =SUMIFS(MOVEMENTS!$E:$E,MOVEMENTS!$D:$D,$B36,MOVEMENTS!$F:$F,"Used on House") | G36: =C36-D36+E36-F36
B37: Caping joiner black | C37: 48 | D37: =SUMIFS(MOVEMENTS!$E:$E,MOVEMENTS!$D:$D,$B37,MOVEMENTS!$F:$F,"Delivery to House") | E37: =SUMIFS(MOVEMENTS!$E:$E,MOVEMENTS!$D:$D,$B37,MOVEMENTS!$F:$F,"Return to Warehouse") | F37: =SUMIFS(MOVEMENTS!$E:$E,MOVEMENTS!$D:$D,$B37,MOVEMENTS!$F:$F,"Used on House") | G37: =C37-D37+E37-F37
B38: Caping joiner brown | C38: 60 | D38: =SUMIFS(MOVEMENTS!$E:$E,MOVEMENTS!$D:$D,$B38,MOVEMENTS!$F:$F,"Delivery to House") | E38: =SUMIFS(MOVEMENTS!$E:$E,MOVEMENTS!$D:$D,$B38,MOVEMENTS!$F:$F,"Return to Warehouse") | F38: =SUMIFS(MOVEMENTS!$E:$E,MOVEMENTS!$D:$D,$B38,MOVEMENTS!$F:$F,"Used on House") | G38: =C38-D38+E38-F38
B39: Corner outside white | C39: 24 | D39: =SUMIFS(MOVEMENTS!$E:$E,MOVEMENTS!$D:$D,$B39,MOVEMENTS!$F:$F,"Delivery to House") | E39: =SUMIFS(MOVEMENTS!$E:$E,MOVEMENTS!$D:$D,$B39,MOVEMENTS!$F:$F,"Return to Warehouse") | F39: =SUMIFS(MOVEMENTS!$E:$E,MOVEMENTS!$D:$D,$B39,MOVEMENTS!$F:$F,"Used on House") | G39: =C39-D39+E39-F39
... B55: Blue plastic protection window | C55: 6 | D55: =SUMIFS(MOVEMENTS!$E:$E,MOVEMENTS!$D:$D,$B55,MOVEMENTS!$F:$F,"Delivery to House") | E55: =SUMIFS(MOVEMENTS!$E:$E,MOVEMENTS!$D:$D,$B55,MOVEMENTS!$F:$F,"Return to Warehouse") | F55: =SUMIFS(MOVEMENTS!$E:$E,MOVEMENTS!$D:$D,$B55,MOVEMENTS!$F:$F,"Used on House") | G55: =C55-D55+E55-F55
...

Sheet MATERIAL_PRICES
A1: Material ID | B1: Material | C1: Unit | D1: Supplier | E1: New Price (€) | F1: Previous Price (€) | G1: Difference (€) | H1: Change % | I1: Last Invoice | J1: Last Updated
B2: Mortage bags(Glue) | C2: bag | D2: Test Supplier A | E2: 12.5 | F2: 12.5 | G2: =E2-F2 | H2: =IF(F2=0,"",G2/F2) | I2: TEST-INV-1001 | J2: 11/09/2026
B3: Soil bend 110mm x 90deg S/S black | C3: bale | D3: Test Supplier A | E3: 48 | F3: 48 | G3: =E3-F3 | H3: =IF(F3=0,"",G3/F3) | I3: TEST-INV-1001 | J3: 11/09/2026
A4: 12236 | B4: Board 20mm white | C4: roll | D4: Test Supplier A | E4: 72 | F4: 72 | G4: =E4-F4 | H4: =IF(F4=0,"",G4/F4) | I4: TEST-INV-1001 | J4: 11/09/2026
B5: Glue | C5: each | D5: Test Supplier A | E5: 14 | F5: 14 | G5: =E5-F5 | H5: =IF(F5=0,"",G5/F5) | I5: TEST-INV-1001 | J5: 11/09/2026
A6: 20921 | B6: Window profile (2.4m) | C6: bag | D6: Test Supplier A | E6: 75 | F6: 75 | G6: =E6-F6 | H6: =IF(F6=0,"",G6/F6) | I6: TEST-INV-1001 | J6: 11/09/2026
A7: 22593 | B7: Starter track 100mm (2m) | C7: bale | D7: Test Supplier A | E7: 46.5 | F7: 46.5 | G7: =E7-F7 | H7: =IF(F7=0,"",G7/F7) | I7: TEST-INV-1001 | J7: 11/09/2026
B8: Downpipe brackets short brown | C8: roll | D8: Test Supplier A | E8: 7 | F8: 1 | G8: =E8-F8 | H8: =IF(F8=0,"",G8/F8) | I8: TEST-INV-1007 | J8: 2026-09-11
B9: Boby bag | C9: each | D9: Test Supplier C | E9: 7 | F9: 16.28 | G9: =E9-F9 | H9: =IF(F9=0,"",G9/F9) | I9: TEST-INV-1008 | J9: 2026-09-11
B10: Gun foam fp404 pink | C10: bag | D10: Test Supplier A | E10: 7 | F10: 0 | G10: =E10-F10 | H10: =IF(F10=0,"",G10/F10) | I10: TEST-INV-1009 | J10: 2026-09-11
B11: Board 100mm | C11: bale | D11: Test Supplier B | E11: 7 | F11: 62.4 | G11: =E11-F11 | H11: =IF(F11=0,"",G11/F11) | I11: TEST-INV-1010 | J11: 2026-09-11
B12: Primer | C12: roll | D12: Test Supplier A | E12: 7 | F12: 32.45 | G12: =E12-F12 | H12: =IF(F12=0,"",G12/F12) | I12: TEST-INV-1011 | J12: 2026-09-11
B13: Downpipe white | C13: each | D13: Test Supplier C | E13: 7 | F13: 9.9 | G13: =E13-F13 | H13: =IF(F13=0,"",G13/F13) | I13: TEST-INV-1012 | J13: 2026-09-11

Sheet SUPPLIERS
A1: Supplier ID | B1: Supplier Name | C1: Contact | D1: Active
A2: SUP-001 | B2: Test Supplier A | C2: test@example.com | D2: Yes
A3: SUP-002 | B3: Test Supplier B | C3: test@example.com | D3: Yes
A4: SUP-003 | B4: Test Supplier C | C4: test@example.com | D4: Yes

Sheet INVOICES
A1: Invoice No. | B1: Supplier | C1: Invoice Date | D1: PDF File | E1: Invoice Total (€) | F1: Checked
A2: TEST-INV-1001 | B2: Test Supplier A | C2: 2026-09-11 | D2: Test_Invoice_Supplier_A_1001.pdf | E2: 2140 | F2: No
A3: TEST-INV-1002 | B3: Test Supplier B | C3: 2026-09-11 | D3: Test_Invoice_Supplier_B_1002.pdf | E3: 1585 | F3: No

Sheet INVOICE_ITEMS
A1: Invoice No. | B1: Material ID | C1: Material | D1: Quantity | E1: Unit Price (€) | F1: VAT % | G1: Line Total (€)
A2: TEST-INV-1001 | C2: Mortage bags(Glue) | D2: 20 | E2: 12.5 | F2: 23 | G2: =D2*E2
A3: TEST-INV-1001 | C3: Soil bend 110mm x 90deg S/S black | D3: 30 | E3: 48 | F3: 23 | G3: =D3*E3
A4: TEST-INV-1001 | B4: 12236 | C4: Board 20mm white | D4: 15 | E4: 72 | F4: 23 | G4: =D4*E4
A5: TEST-INV-1001 | C5: Glue | D5: 40 | E5: 14 | F5: 23 | G5: =D5*E5
A6: TEST-INV-1001 | B6: 20921 | C6: Window profile (2.4m) | D6: 10 | E6: 75 | F6: 23 | G6: =D6*E6
A7: TEST-INV-1001 | B7: 22593 | C7: Starter track 100mm (2m) | D7: 25 | E7: 46.5 | F7: 23 | G7: =D7*E7
A8: TEST-INV-1002 | C8: Downpipe brackets short brown | D8: 20 | E8: 9.8 | F8: 23 | G8: =D8*E8
A9: TEST-INV-1002 | C9: Boby bag | D9: 30 | E9: 18.5 | F9: 23 | G9: =D9*E9
A10: TEST-INV-1002 | C10: Gun foam fp404 pink | D10: 15 | E10: 22 | F10: 23 | G10: =D10*E10
A11: TEST-INV-1002 | C11: Board 100mm | D11: 40 | E11: 65 | F11: 23 | G11: =D11*E11
A12: TEST-INV-1002 | C12: Primer | D12: 10 | E12: 31.5 | F12: 23 | G12: =D12*E12
A13: TEST-INV-1002 | C13: Downpipe white | D13: 25 | E13: 11.25 | F13: 23 | G13: =D13*E13
A14: TEST-INV-1001 | C14: Mortage bags(Glue) | D14: 20 | E14: 12.5 | F14: 250
A15: TEST-INV-1001 | C15: Soil bend 110mm x 90deg S/S black | D15: 20 | E15: 48 | F15: 960
A16: TEST-INV-1001 | B16: 12236 | C16: Board 20mm white | D16: 20 | E16: 72 | F16: 1440
A17: TEST-INV-1001 | C17: Glue | D17: 20 | E17: 14 | F17: 280
A18: TEST-INV-1001 | B18: 20921 | C18: Window profile (2.4m) | D18: 20 | E18: 75 | F18: 1500
A19: TEST-INV-1001 | B19: 22593 | C19: Starter track 100mm (2m) | D19: 20 | E19: 46.5 | F19: 930
A20: TEST-INV-1001 | C20: Mortage bags(Glue) | D20: 20 | E20: 12.5 | F20: 250
A21: TEST-INV-1001 | C21: Soil bend 110mm x 90deg S/S black | D21: 20 | E21: 48 | F21: 960
A22: TEST-INV-1001 | B22: 12236 | C22: Board 20mm white | D22: 20 | E22: 72 | F22: 1440
A23: TEST-INV-1001 | C23: Glue | D23: 20 | E23: 14 | F23: 280
A24: TEST-INV-1001 | B24: 20921 | C24: Window profile (2.4m) | D24: 20 | E24: 75 | F24: 1500
A25: TEST-INV-1001 | B25: 22593 | C25: Starter track 100mm (2m) | D25: 20 | E25: 46.5 | F25: 930
A26: TEST-INV-1001 | C26: Mortage bags(Glue) | D26: 20 | E26: 12.5 | F26: 250
A27: TEST-INV-1001 | C27: Soil bend 110mm x 90deg S/S black | D27: 20 | E27: 48 | F27: 960
A28: TEST-INV-1001 | B28: 12236 | C28: Board 20mm white | D28: 20 | E28: 72 | F28: 1440
A29: TEST-INV-1001 | C29: Glue | D29: 20 | E29: 14 | F29: 280
A30: TEST-INV-1001 | B30: 20921 | C30: Window profile (2.4m) | D30: 20 | E30: 75 | F30: 1500
A31: TEST-INV-1001 | B31: 22593 | C31: Starter track 100mm (2m) | D31: 20 | E31: 46.5 | F31: 930
A32: TEST-INV-1001 | C32: Mortage bags(Glue) | D32: 20 | E32: 12.5 | F32: 250
A33: TEST-INV-1001 | C33: Soil bend 110mm x 90deg S/S black | D33: 20 | E33: 48 | F33: 960
A34: TEST-INV-1001 | B34: 12236 | C34: Board 20mm white | D34: 20 | E34: 72 | F34: 1440
A35: TEST-INV-1001 | C35: Glue | D35: 20 | E35: 14 | F35: 280
A36: TEST-INV-1001 | B36: 20921 | C36: Window profile (2.4m) | D36: 20 | E36: 75 | F36: 1500
A37: TEST-INV-1001 | B37: 22593 | C37: Starter track 100mm (2m) | D37: 20 | E37: 46.5 | F37: 930
A38: TEST-INV-1001 | C38: Mortage bags(Glue) | D38: 20 | E38: 12.5 | F38: 250
A39: TEST-INV-1001 | C39: Soil bend 110mm x 90deg S/S black | D39: 20 | E39: 48 | F39: 960
A40: TEST-INV-1001 | B40: 12236 | C40: Board 20mm white | D40: 20 | E40: 72 | F40: 1440
...

Sheet PRICE_HISTORY
A1: Date | B1: Material ID | C1: Material | D1: Supplier | E1: Price (€) | F1: Invoice No.
A2: 2026-08-15 | C2: Mortage bags(Glue) | D2: Test Supplier A | E2: 11.5 | F2: TEST-OLD-901
A3: 2026-09-11 | C3: Mortage bags(Glue) | D3: Test Supplier A | E3: 12.5 | F3: TEST-INV-1001
A4: 2026-08-15 | C4: Soil bend 110mm x 90deg S/S black | D4: Test Supplier B | E4: 46.08 | F4: TEST-OLD-902
A5: 2026-09-11 | C5: Soil bend 110mm x 90deg S/S black | D5: Test Supplier B | E5: 48 | F5: TEST-INV-1001
A6: 2026-08-15 | B6: 12236 | C6: Board 20mm white | D6: Test Supplier A | E6: 74.16 | F6: TEST-OLD-903
A7: 2026-09-11 | B7: 12236 | C7: Board 20mm white | D7: Test Supplier A | E7: 72 | F7: TEST-INV-1001
A8: 2026-08-15 | C8: Glue | D8: Test Supplier C | E8: 12.32 | F8: TEST-OLD-904
A9: 2026-09-11 | C9: Glue | D9: Test Supplier C | E9: 14 | F9: TEST-INV-1001
A10: 2026-08-15 | B10: 20921 | C10: Window profile (2.4m) | D10: Test Supplier A | E10: 69 | F10: TEST-OLD-905
A11: 2026-09-11 | B11: 20921 | C11: Window profile (2.4m) | D11: Test Supplier A | E11: 75 | F11: TEST-INV-1001
A12: 2026-08-15 | B12: 22593 | C12: Starter track 100mm (2m) | D12: Test Supplier B | E12: 44.64 | F12: TEST-OLD-906
A13: 2026-09-11 | B13: 22593 | C13: Starter track 100mm (2m) | D13: Test Supplier B | E13: 46.5 | F13: TEST-INV-1001
A14: 2026-08-15 | C14: Downpipe brackets short brown | D14: Test Supplier A | E14: 10.09 | F14: TEST-OLD-907
A15: 2026-09-11 | C15: Downpipe brackets short brown | D15: Test Supplier A | E15: 9.8 | F15: TEST-INV-1002
A16: 2026-08-15 | C16: Boby bag | D16: Test Supplier C | E16: 16.28 | F16: TEST-OLD-908
A17: 2026-09-11 | C17: Boby bag | D17: Test Supplier C | E17: 18.5 | F17: TEST-INV-1002
A18: 2026-08-15 | C18: Gun foam fp404 pink | D18: Test Supplier A | E18: 20.24 | F18: TEST-OLD-909
A19: 2026-09-11 | C19: Gun foam fp404 pink | D19: Test Supplier A | E19: 22 | F19: TEST-INV-1002
A20: 2026-08-15 | C20: Board 100mm | D20: Test Supplier B | E20: 62.4 | F20: TEST-OLD-910
A21: 2026-09-11 | C21: Board 100mm | D21: Test Supplier B | E21: 65 | F21: TEST-INV-1002
A22: 2026-08-15 | C22: Primer | D22: Test Supplier A | E22: 32.45 | F22: TEST-OLD-911
A23: 2026-09-11 | C23: Primer | D23: Test Supplier A | E23: 31.5 | F23: TEST-INV-1002
A24: 2026-08-15 | C24: Downpipe white | D24: Test Supplier C | E24: 9.9 | F24: TEST-OLD-912
A25: 2026-09-11 | C25: Downpipe white | D25: Test Supplier C | E25: 11.25 | F25: TEST-INV-1002
... A27: 11/09/2026 | C27: Soil bend 110mm x 90deg S/S black | D27: Test Supplier A | E27: 48 | F27: TEST-INV-1001
A28: 11/09/2026 | B28: 12236 | C28: Board 20mm white | D28: Test Supplier A | E28: 72 | F28: TEST-INV-1001
A29: 11/09/2026 | C29: Glue | D29: Test Supplier A | E29: 14 | F29: TEST-INV-1001
A30: 11/09/2026 | B30: 20921 | C30: Window profile (2.4m) | D30: Test Supplier A | E30: 75 | F30: TEST-INV-1001
A31: 11/09/2026 | B31: 22593 | C31: Starter track 100mm (2m) | D31: Test Supplier A | E31: 46.5 | F31: TEST-INV-1001
A32: 11/09/2026 | C32: Mortage bags(Glue) | D32: Test Supplier A | E32: 12.5 | F32: TEST-INV-1001
A33: 11/09/2026 | C33: Soil bend 110mm x 90deg S/S black | D33: Test Supplier A | E33: 48 | F33: TEST-INV-1001
A34: 11/09/2026 | B34: 12236 | C34: Board 20mm white | D34: Test Supplier A | E34: 72 | F34: TEST-INV-1001
A35: 11/09/2026 | C35: Glue | D35: Test Supplier A | E35: 14 | F35: TEST-INV-1001
A36: 11/09/2026 | B36: 20921 | C36: Window profile (2.4m) | D36: Test Supplier A | E36: 75 | F36: TEST-INV-1001
A37: 11/09/2026 | B37: 22593 | C37: Starter track 100mm (2m) | D37: Test Supplier A | E37: 46.5 | F37: TEST-INV-1001
A38: 11/09/2026 | C38: Mortage bags(Glue) | D38: Test Supplier A | E38: 12.5 | F38: TEST-INV-1001
A39: 11/09/2026 | C39: Soil bend 110mm x 90deg S/S black | D39: Test Supplier A | E39: 48 | F39: TEST-INV-1001
A40: 11/09/2026 | B40: 12236 | C40: Board 20mm white | D40: Test Supplier A | E40: 72 | F40: TEST-INV-1001
A41: 11/09/2026 | C41: Glue | D41: Test Supplier A | E41: 14 | F41: TEST-INV-1001
...
